Workbook

Sheet اليومية الامريكية
E1: الإجمالي | G1: الصندوق | I1: البنك | K1: المخزون | M1: ضريبة القيمة المضافة | O1: ضريبة أرباح تجارية | Q1: تكلفة المبيعات | S1: المبيعات | U1: خصم مسموح به | W1: الموردين | Y1: العملاء | AA1: خصم مكتسب به | AC1: عهدة | AE1: ميزانية عمومية | AG1: الدائنون | AI1: مصروف الاهلاك | AK1: مجمع الاهلاك
A2: التسلسل | B2: التاريخ | C2: رقم القيد | D2: البيان | E2: مدين | F2: دائن | G2: مدين | H2: دائن | I2: مدين | J2: دائن | K2: مدين | L2: دائن | M2: مدين | N2: دائن | O2: مدين | P2: دائن | Q2: مدين | R2: دائن | S2: مدين | T2: دائن | U2: مدين | V2: دائن | W2: مدين | X2: دائن | Y2: مدين | Z2: دائن | AA2: مدين | AB2: دائن | AC2: مدين | AD2: دائن | AE2: مدين | AF2: دائن | AG2: مدين | AH2: دائن | AI2: مدين | AJ2: دائن | AK2: مدين | AL2: دائن
A3: 1 | B3: 44927 | C3: 1 | D3: عملية شراء بضاعة | E3: =SUMIF($G$2:$AL$2,$G$2,G3:AL9) -> 70110 | F3: =SUMIF($G$2:$AL$2,$G$2,H3:AM9) -> 70110 | J3: 69495 | K3: 61500 | M3: 8610 | P3: 615
A4: =A3+1 -> 2 | B4: 44928 | C4: 2 | D4: شراء بضاعة | E4: =SUMIF($G$2:$AL$2,$G$2,G4:AL10) -> 93480 | F4: =SUMIF($G$2:$AL$2,$G$2,H4:AM10) -> 93480 | J4: 92660 | K4: 82000 | M4: 11480 | P4: 820
A5: =A4+1 -> 3 | B5: 44929 | C5: 3 | D5: شراء بضاعة | E5: =SUMIF($G$2:$AL$2,$G$2,G5:AL11) -> 193980 | F5: =SUMIF($G$2:$AL$2,$G$2,H5:AM11) -> 193980 | G5: 120910 | L5: 72000 | N5: 14980 | O5: 1070 | Q5: 72000 | T5: 107000
A6: =A5+1 -> 4 | B6: 44930 | C6: 4 | D6: بيع بضاعة | E6: =SUMIF($G$2:$AL$2,$G$2,G6:AL12) -> 49305 | F6: =SUMIF($G$2:$AL$2,$G$2,H6:AM12) -> 49305 | J6: 48872 | K6: 43250 | M6: 6055 | P6: 433
A7: =A6+1 -> 5 | B7: 44931 | C7: 5 | D7: شراء بضاعة | E7: =SUMIF($G$2:$AL$2,$G$2,G7:AL13) -> 100030 | F7: =SUMIF($G$2:$AL$2,$G$2,H7:AM13) -> 100030 | G7: 56160 | L7: 40750 | N7: 7280 | O7: 520 | Q7: 40750 | T7: 52000 | U7: 2600
A8: =A7+1 -> 6 | B8: 44932 | C8: 6 | D8: سداد مورد | E8: =SUMIF($G$2:$AL$2,$G$2,G8:AL14) -> 41040 | F8: =SUMIF($G$2:$AL$2,$G$2,H8:AM14) -> 41040 | J8: 38880 | P8: 360 | W8: 41040 | AB8: 1800
A9: =A8+1 -> 7 | B9: 44933 | C9: 7 | D9: سداد عميل | E9: =SUMIF($G$2:$AL$2,$G$2,G9:AL15) -> 79800 | F9: =SUMIF($G$2:$AL$2,$G$2,H9:AM15) -> 79800 | G9: 77700 | O9: 700 | U9: 1400 | Z9: 79800
A10: إجمالي شهر يناير | E10: =SUM(E3:E9) -> 627745 | F10: =SUM(F3:F9) -> 627745 | G10: =SUM(G3:G9) -> 254770 | H10: =SUM(H3:H9) -> 0 | I10: =SUM(I3:I9) -> 0 | J10: =SUM(J3:J9) -> 249907 | K10: =SUM(K3:K9) -> 186750 | L10: =SUM(L3:L9) -> 112750 | ... AL10: =SUM(AL3:AL9) -> 0
A11: 1 | B11: 44958 | C11: 1 | D11: استعاضة عهدة | E11: =SUMIF($G$2:$AL$2,$G$2,G11:AL15) -> 30000 | F11: =SUMIF($G$2:$AL$2,$G$2,H11:AM15) -> 30000 | J11: 30000 | AC11: 30000
A12: =A11+1 -> 2 | B12: 44959 | C12: 2 | D12: تسوية عهدة | E12: =SUMIF($G$2:AL3,$G$2,G12:AL16) -> 1100 | F12: =SUMIF($G$2:AM3,$G$2,H12:AM16) -> 1100 | AD12: 1100 | AE12: 1100
A13: =A12+1 -> 3 | B13: 44960 | C13: 3 | D13: تسوية عهدة | E13: =SUMIF($G$2:AL4,$G$2,G13:AL17) -> 1500 | F13: =SUMIF($G$2:AM4,$G$2,H13:AM17) -> 1500 | AD13: 1500 | AE13: 1500
A14: =A13+1 -> 4 | B14: 44961 | C14: 4 | D14: استعاضة عهدة | E14: =SUMIF($G$2:AL5,$G$2,G14:AL18) -> 30000 | F14: =SUMIF($G$2:AM5,$G$2,H14:AM18) -> 30000 | J14: 30000 | AC14: 30000
A15: =A14+1 -> 5 | B15: 44962 | C15: 5 | D15: اهلاك مدة | E15: =SUMIF($G$2:AL6,$G$2,G15:AL19) -> 30000 | F15: =SUMIF($G$2:AM6,$G$2,H15:AM19) -> 30000 | AI15: 30000 | AL15: 30000
A16: إجمالي شهر فبراير | E16: =SUM(E11:E15) -> 92600 | F16: =SUM(F11:F15) -> 92600 | G16: =SUM(G11:G15) -> 0 | H16: =SUM(H11:H15) -> 0 | I16: =SUM(I11:I15) -> 0 | J16: =SUM(J11:J15) -> 60000 | K16: =SUM(K11:K15) -> 0 | L16: =SUM(L11:L15) -> 0 | ... AL16: =SUM(AL11:AL15) -> 30000
A18: إجمالي الشهور | E18: =E10+E16 -> 720345 | F18: =F10+F16 -> 720345 | G18: =G10+G16 -> 254770 | H18: =H10+H16 -> 0 | I18: =I10+I16 -> 0 | J18: =J10+J16 -> 309907 | K18: =K10+K16 -> 186750 | L18: =L10+L16 -> 112750 | ... AL18: =AL10+AL16 -> 30000

Sheet ميزان المراجعة 
A1: ميزان مراجعة الشركة
A2: البيان | B2: اول المدة | D2: الحركة | F2: الرصيد
B3: مدين | C3: دائن | D3: مدين | E3: دائن | F3: مدين | G3: دائن
A4: الأصول الثابتة | B4: 2000000 | C4: 0 | D4: 0 | E4: 0 | F4: =B4+D4-C4-E4 -> 2000000 | G4: 0 | H4: =F4+F5+F6+F7+F8+F9+F14+F15+F17+F19+F21+F22+F25+F23 -> 3256988
A5: الصندوق | B5: 5000 | C5: 0 | D5: ='اليومية الامريكية'!G18 -> 254770 | E5: ='اليومية الامريكية'!H18 -> 0 | F5: =B5+D5-C5-E5 -> 259770 | G5: 0 | H5: =G10+G11+G12+G13+G16+G18+G20+G24 -> 3256988
A6: البنك | B6: 1000000 | C6: 0 | D6: ='اليومية الامريكية'!I18 -> 0 | E6: ='اليومية الامريكية'!J18 -> 309907 | F6: =B6+D6-C6-E6 -> 690093 | G6: 0
A7: أوراق القبض | B7: 10000 | C7: 0 | D7: 0 | E7: 0 | F7: =B7+D7-C7-E7 -> 10000 | G7: 0
A8: العملاء | B8: 50000 | C8: 0 | D8: ='اليومية الامريكية'!Y18 -> 0 | E8: ='اليومية الامريكية'!Z18 -> 79800 | F8: =B8+D8-C8-E8 -> -29800 | G8: 0
A9: تأمينات لدى الغير | B9: 40000 | C9: 0 | D9: 0 | E9: 0 | F9: =B9+D9-C9-E9 -> 40000 | G9: =E9+C9-D9 -> 0
A10: رأس المال | B10: 0 | C10: 3000000 | D10: 0 | E10: 0 | F10: =B10+D10-E10 -> 0 | G10: =C10+E10-D10-B10 -> 3000000
A11: موردين | B11: 0 | C11: 54000 | D11: ='اليومية الامريكية'!W18 -> 41040 | E11: ='اليومية الامريكية'!X18 -> 0 | F11: 0 | G11: =C11+E11-D11-B11 -> 12960
A12: أوراق الدفع | B12: 0 | C12: 6000 | D12: 0 | E12: 0 | F12: 0 | G12: =C12+E12-D12-B12 -> 6000
A13: تأمينات للغير | B13: 0 | C13: 45000 | D13: 0 | E13: 0 | F13: =B13+D13-E13 -> 0 | G13: =C13+E13-D13-B13 -> 45000
A14: المخزون | B14: 0 | C14: 0 | D14: ='اليومية الامريكية'!K18 -> 186750 | E14: ='اليومية الامريكية'!L18 -> 112750 | F14: =B14+D14-E14 -> 74000 | G14: 0
A15: تكلفة المبيعات | B15: 0 | C15: 0 | D15: ='اليومية الامريكية'!Q18 -> 112750 | E15: ='اليومية الامريكية'!R18 -> 0 | F15: =B15+D15-E15 -> 112750 | G15: 0
A16: المبيعات | B16: 0 | C16: 0 | D16: ='اليومية الامريكية'!S18 -> 0 | E16: ='اليومية الامريكية'!T18 -> 159000 | F16: 0 | G16: =E16+C16-D16 -> 159000
A17: ضريبة القيمة المضافة | B17: 0 | C17: 0 | D17: ='اليومية الامريكية'!M18 -> 26145 | E17: ='اليومية الامريكية'!N18 -> 22260 | F17: =B17+D17-E17 -> 3885 | G17: 0
A18: خصم المكتسب به | B18: 0 | C18: 0 | D18: ='اليومية الامريكية'!AA18 -> 0 | E18: ='اليومية الامريكية'!AB18 -> 1800 | F18: 0 | G18: =E18+C18-D18 -> 1800
A19: ضريبة أرباح تجارية مدينة | B19: 0 | C19: 0 | D19: ='اليومية الامريكية'!O18 -> 2290 | E19: 0 | F19: =B19+D19-E19 -> 2290 | G19: 0
A20: ضريبة أرباح تجارية دائنة | B20: 0 | C20: 0 | D20: 0 | E20: ='اليومية الامريكية'!P18 -> 2228 | F20: 0 | G20: =E20+C20-D20 -> 2228
A21: العهد | B21: 0 | C21: 0 | D21: ='اليومية الامريكية'!AC18 -> 60000 | E21: ='اليومية الامريكية'!AD18 -> 2600 | F21: =B21+D21-E21 -> 57400 | G21: 0
A22: الميزانية العمومية | B22: 0 | C22: 0 | D22: ='اليومية الامريكية'!AE18 -> 2600 | E22: ='اليومية الامريكية'!AF18 -> 0 | F22: =B22+D22-E22 -> 2600 | G22: 0
A23: مصروف الاهلاك | B23: 0 | C23: 0 | D23: ='اليومية الامريكية'!AI18 -> 30000 | E23: ='اليومية الامريكية'!AJ18 -> 0 | F23: =B23+D23-E23 -> 30000 | G23: 0
A24: مجمع الاهلاك | B24: 0 | C24: 0 | D24: ='اليومية الامريكية'!AK18 -> 0 | E24: ='اليومية الامريكية'!AL18 -> 30000 | F24: 0 | G24: =E24+C24-D24 -> 30000
A25: خصم مسموح به | B25: 0 | C25: 0 | D25: ='اليومية الامريكية'!U18 -> 4000 | E25: ='اليومية الامريكية'!V18 -> 0 | F25: =B25+D25-E25 -> 4000 | G25: 0
A26: الإجمالي | B26: =SUM(B4:B25) -> 3105000 | C26: =SUM(C4:C25) -> 3105000 | D26: =SUM(D4:D25) -> 720345 | E26: =SUM(E4:E25) -> 720345 | F26: =SUM(F4:F25) -> 3256988 | G26: =SUM(G4:G25) -> 3256988

Sheet الإيضاحات المتممة
A1: الإيضاحات المتممة للشركة
A2: البيان | B2: ر.س
A3: مباني | B3: 500000
A4: سيارات | B4: 500000
A5: الالات | B5: 500000
A6: اثاث | B6: 500000
A7: الإجمالي | B7: =SUM(B3:B6) -> 2000000
A8: مشروعات تحت التنفيذ
A9: البيان | B9: ر.س
A10: تكوين سلعي | B10: 0
A11: انفاق استمثارية | B11: 0
A12: الإجمالي | B12: =SUM(B10:B11) -> 0
A13: نقدية بالبنك والصندوق
A14: البيان | B14: ر.س
A15: الصندوق | B15: ='ميزان المراجعة '!F5 -> 259770
A16: البنك | B16: ='ميزان المراجعة '!F6 -> 690093
A17: الإجمالي | B17: =SUM(B15:B16) -> 949863
A18: صافي الإيرادات
A19: البيان | B19: ر.س
A20: المبيعات - الإيرادات | B20: ='ميزان المراجعة '!G16 -> 159000
A21: يخصم
A22: مردودات المبيعات | B22: 0
A23: الخصم المسموح به | B23: ='ميزان المراجعة '!F25 -> 4000
A24: الإجمالي | B24: =B20-B22-B23 -> 155000
A25: أصول أخرى غير ملموسة
A26: البيان | B26: ر.س
A27: شهرة | B27: 0
A28: حق امتياز | B28: 0
A29: الإجمالي | B29: =SUM(B27:B28) -> 0
A30: بنوك دائنة
A31: البيان | B31: ر.س
A32: سحب على المكشوف | B32: 0
A33: تسهيلات ائتمانية | B33: 0
A34: الإجمالي | B34: =SUM(B32:B33) -> 0
A35: تكلفة المبيعات جرد مستمر
A36: البيان | B36: ر.س
A37: تكلفة المبيعات جرد مستمر | B37: ='ميزان المراجعة '!F15 -> 112750
A38: يخصم
A39: خصم مكتسب | B39: ='ميزان المراجعة '!G18 -> 1800
A40: الإجمالي | B40: =B37-B39 -> 110950
...

Sheet قائمة الدخل
A1: قائمة دخل الشركة من | C1: كيف وصلنا لهذا (كل هذه الأرقام يتم الحصول عليها من ميزان المراجعة والإيضاحات)
A2: 44927 | B2: 44962
A3: البيان | B3: ر.س
A4: صافي المبيعات - الإيرادات | B4: ='الإيضاحات المتممة'!B24 -> 155000 | C4: المبيعات - مردودات المبيعات - الخصم المسموح به
A5: يخصم | C5: نطرح منه
A6: تكلفة المبيعات | B6: ='الإيضاحات المتممة'!B40 -> 110950 | C6: تكلفة البضاعة المباعة (تحسب من خلال قائمة التكاليف)
A7: مجمل الربح والخسارة | B7: =B4-B6 -> 44050 | C7: الناتج
A8: يضاف
A9: إيرادات أخرى | B9: 0 | C9: أي إيرادات من أنشطة غير المبيعات (خدمات أخرى )
A10: أرباح رأس مالية | B10: 0 | C10: الإيرادات الناتجة من بيع الأصول الثابتة
A11: فروق عملة دائنة | B11: 0 | C11: أرباح ناتجة من فرق تقييم العملات الأجنبية
A12: فوائد دائنة | B12: 0 | C12: فوائد مستحقة للشركة لدى الغير
A13: يخصم | C13: طرح
A14: مصاريف تسويقية | B14: 0 | C14: مصاريف البيع والتسويق والدعايا والإعلان
A15: مصروفات اهلاك | B15: ='ميزان المراجعة '!F23 -> 30000 | C15: قسط الإهلاك السنوي للأصول الثابتة
A16: خسارة رأس مالية | B16: 0 | C16: قيمة الخسارة من بيع الأصول (إذا كان سعر البيع أقل من قيمته الدفترية)
A17: خسائر انخفاض القيمة | B17: 0 | C17: خسائر من انخفاض القيمة الدفترية للأصول (بسبب التقادم أو تلف)
A18: فروق عملة مدينة | B18: 0 | C18: صافي خسائر فروق تقييم العملات الأجنبية
A19: فوائد مدينة | B19: 0 | C19: الفوائد المستحقة على المنشأة مثل فوائد القروض
A20: صافي الربح - الخسارة | B20: =B7+SUM(B9:B12)-SUM(B14:B19) -> 14050 | C20: ناتج العمليات السابقة
C21: صافي نتائج أعمال المنشأة ويخصم منه الضرائب لاحقًا لحساب (صافي الدخل بعد الضارئب)

Sheet قائمة المركز المالي 
A1: 05/02/2023 المركز المالي
A2: البيان | B2: ر.س
A3: الأصول غير المتداولة
A4: الأصول الثابتة بالصافي | B4: ='الإيضاحات المتممة'!B7 -> 2000000
A5: مشروعات تحت التنفيذ | B5: 0
A6: استثمارات طويلة الأجل | B6: 0
A7: أصول أخرى | B7: 0
A8: اجمالي الأصول الغير متداولة | B8: =SUM(B4:B7) -> 2000000
A9: الأصول المتداولة
A10: المخزون | B10: ='ميزان المراجعة '!F14 -> 74000
A11: العملاء | B11: ='ميزان المراجعة '!F8 -> -29800
A12: أوراق القبض | B12: ='ميزان المراجعة '!F7 -> 10000
A13: مدينون وارصدة مدينة أخرى | B13: ='الإيضاحات المتممة'!B49 -> 103575
A14: استمثارات قصيرة الاجل | B14: 0
A15: ميزانية عمومية | B15: ='ميزان المراجعة '!F22 -> 2600
A16: نقدية بالبنك والصندوق | B16: ='الإيضاحات المتممة'!B17 -> 949863
A17: اجمالي الأصول متداولة | B17: =SUM(B10:B16) -> 1110238
A18: اجمالي الأصول | B18: =B8+B17 -> 3110238
A19: الإلتزامات الغير متداولة وحقوق الملكية
A20: حقوق ملكية
A21: راس المال | B21: ='ميزان المراجعة '!G10 -> 3000000
A22: جاري الشركاء | B22: 0
A23: أرباح وخسائر مرحلة
A24: أرباح وخسائر العام | B24: ='قائمة الدخل'!B20 -> 14050
A25: احتياطات | B25: 0
A26: إجمالي حقوق الملكية | B26: =SUM(B21:B25) -> 3014050
A27: الالتزامات الغير متداولة
A28: قروض | B28: 0
A29: سندات | B29: 0
A30: اجمالي الالتزامات الغير متداولة | B30: =SUM(B28:B29) -> 0
A31: الالتزامات متداولة
A32: بنوك دائنة | B32: ='ميزان المراجعة '!G6 -> 0
A33: موردين - أوراق الدفع | B33: ='ميزان المراجعة '!G11+'ميزان المراجعة '!G12 -> 18960 | O33: @
A34: مخصصات | B34: 0
A35: الجزء المسدد من القرض خلال السنة | B35: 0
A36: مجمع الإهلاك | B36: ='ميزان المراجعة '!G24 -> 30000
A37: دائنون وارصدة دائنة أخرى | B37: ='الإيضاحات المتممة'!B57 -> 47228
A38: اجمالي الالتزامات متداولة | B38: =SUM(B32:B37) -> 96188
A39: اجمالي الإلتزامات وحقوق الملكية | B39: =B26+B30+B38 -> 3110238
