Workbook

Sheet السؤال
A1: السؤال ميزان المراجعة | C1: المعطى
A2: الموجودات | B2: البيان | C2: شركة السلام هي شركة للبيع التجزئة، بدأت اعمالها في بداية سنة٢٠٢٥
A3: الاصول الثابته | B3: 200000 | C3: قامت الشركة في بداية السنة ١/٢/٢٠٢٥ بعملية شراء بضاعة بقيمة٧٠١١٠ ريال
A4: الصندوق | B4: 5000 | C4: وفي اليوم التالي ٢/٢/٢٠٢٥قامت ايضا بشراء بضاعة بقيمة ٩٣٤٨٠ ريال
A5: البنك | B5: 1000000 | C5: اما في اليوم الثالث ٣/٢/٢٠٢٥ قامت الشركة بعملية بيع بضاعة بقيمة ١٩٤٢٠٠ ريال
A6: اوراق القبض | B6: 10000 | C6: وفي اليوم الرابع٤/٢/٢٠٢٥ قامت الشركة بعملية بيع بضاعة بقيمة٤٩٣٠٥ ريال
A7: العملاء | B7: 100000 | C7: وفي اليوم الخامس ٥/٢/٢٠٢٥قامت الشركة بعملية بيع بضاعة بقيمة١٠٠٠٣٠ ريال
A8: تأمينات لدى الغير | B8: 40000 | C8: وفي اليوم السادس٦/٢/٢٠٢٥قامت الشركة بسداد المورد قيمة٤١٠٠٠ ريال
A9: رأس المال | B9: 1246000 | C9: وفي اليوم السابع والاخير من شهر فبراير سنة٢٠٢٥ قامت الشركة بتسديد عمليتها٧٩٧٠٠ ريال
A10: الموردين | B10: 54000 | C10: وفي الشهر الثاني من شهر مارس قامت الشركة بعملية استعاضة عهدة٣٠٠٠٠ ريال
A11: اوراق الدفع | B11: 10000 | C11: وفي اليوم الثاني٢/٣/٢٠٢٥ قامت شركة السلام بتسوية عهدة١١٠٠ ولليوم الذي يليه بقيمة١٥٠٠ ريال
A12: تامينات للغير | B12: 45000 | C12: اما في اليوم الرابع٤/٣/٢٠٢٥ قامت الشركة باستعاضة عهدة بقيمة٣٠٠٠٠ريال
A13: مباني | B13: 50000 | C13: وفي اليوم الاخير قامت شركة السلام ب اهلاك المدة بقيمة٣٠٠٠٠ريال
A14: سيارات | B14: 50000 | C14: المطلوب
A15: الالات | B15: 50000 | C15: ادخال العمليات المالية لشركة السلام باستخدام النظام المحاسبي بالاكسل
A16: اثاث | B16: 50000

Sheet قيود
E1: الاجمالي | G1: الصندوق | I1: البنك | K1: المخرون | M1: ضريبة القيمة المضافة | O1: ضريبة ارباح تجارية | Q1: تكلفة البضاعة المباعة | S1: المبيعات | U1: خصم مسموح به | W1: الموردين | Y1: العملاء | AA1: خصم مكتسب | AC1: عهدة | AE1: ميزانية عمومية | AG1: الدائنون | AI1: مصروف اهلاك | AK1: مجمع اهلاك
A2: التسلسل | B2: التاريخ | C2: البيان | D2: القيد | E2: مدين | F2: دائن | G2: مدين | H2: دائن | I2: مدين | J2: دائن | K2: مدين | L2: دائن | M2: مدين | N2: دائن | O2: مدين | P2: دائن | Q2: مدين | R2: دائن | S2: مدين | T2: دائن | U2: مدين | V2: دائن | W2: مدين | X2: دائن | Y2: مدين | Z2: دائن | AA2: مدين | AB2: دائن | AC2: مدين | AD2: دائن | AE2: مدين | AF2: دائن | AG2: مدين | AH2: دائن | AI2: مدين | AJ2: دائن | AK2: مدين | AL2: دائن
A3: 1 | E3: =SUMIF($G$2:$AL$2,$G$2,G3:AL12) -> 0 | F3: =SUMIF($G$2:AL$2,$G$2,G3:AL3) -> 0
A4: =A3+1 -> 2
A5: =A4+1 -> 3
A6: =A5+1 -> 4
A7: =A6+1 -> 5
A8: =A7+1 -> 6
A9: =A8+1 -> 7
A10: =A9+1 -> 8
A11: =A10+1 -> 9
A12: =A11+1 -> 10
A13: اجمالي شهر يناير | E13: =SUM(E3:E12) -> 0 | F13: =SUM(F3:F12) -> 0 | G13: =SUM(G3:G12) -> 0 | H13: =SUM(H3:H12) -> 0 | I13: =SUM(I3:I12) -> 0 | J13: =SUM(J3:J12) -> 0 | K13: =SUM(K3:K12) -> 0 | L13: =SUM(L3:L12) -> 0 | ... AL13: =SUM(AL3:AL12) -> 0
A14: 1 | B14: 45689 | C14: عملية شراء بضاعة | D14: 1 | E14: =G14+I14+K14+M14+O14+Q14+S14+U14+W14+Y14+AA14+AC14+AE14+AG14+AG14+AI14+AK14 -> 70110 | F14: =H14+J14+L14+N14+P14+R14+T14+V14+X14+Z14+AB14+AD14+AF14+AH14+AH14+AJ14+AL14 -> 70110 | K14: 70110 | X14: 70110
A15: =A14+1 -> 2 | B15: 45690 | C15: عملية شراء بضاعة | D15: 2 | E15: =G15+I15+K15+M15+O15+Q15+S15+U15+W15+Y15+AA15+AC15+AE15+AG15+AG15+AI15+AK15 -> 93480 | F15: =H15+J15+L15+N15+P15+R15+T15+V15+X15+Z15+AB15+AD15+AF15+AH15+AH15+AJ15+AL15 -> 93480 | K15: 93480 | X15: 93480
A16: =A15+1 -> 3 | B16: 45691 | C16: عملية بيع بضاعة | D16: 3 | E16: =G16+I16+K16+M16+O16+Q16+S16+U16+W16+Y16+AA16+AC16+AE16+AG16+AG16+AI16+AK16 -> 194200 | F16: =H16+J16+L16+N16+P16+R16+T16+V16+X16+Z16+AB16+AD16+AF16+AH16+AH16+AJ16+AL16 -> 194200 | G16: 194200 | T16: 194200
A17: =A16+1 -> 4 | B17: 45692 | C17: عملية بيع بضاعة | D17: 4 | E17: =G17+I17+K17+M17+O17+Q17+S17+U17+W17+Y17+AA17+AC17+AE17+AG17+AG17+AI17+AK17 -> 49305 | F17: =H17+J17+L17+N17+P17+R17+T17+V17+X17+Z17+AB17+AD17+AF17+AH17+AH17+AJ17+AL17 -> 49305 | G17: 49305 | T17: 49305
A18: =A17+1 -> 5 | B18: 45693 | C18: عملية بيع بضاعة | D18: 5 | E18: =G18+I18+K18+M18+O18+Q18+S18+U18+W18+Y18+AA18+AC18+AE18+AG18+AG18+AI18+AK18 -> 100030 | F18: =H18+J18+L18+N18+P18+R18+T18+V18+X18+Z18+AB18+AD18+AF18+AH18+AH18+AJ18+AL18 -> 100030 | G18: 100030 | T18: 100030
A19: =A18+1 -> 6 | B19: 45694 | C19: عملية تسديد للمورد | D19: 6 | E19: =G19+I19+K19+M19+O19+Q19+S19+U19+W19+Y19+AA19+AC19+AE19+AG19+AG19+AI19+AK19 -> 41000 | F19: =H19+J19+L19+N19+P19+R19+T19+V19+X19+Z19+AB19+AD19+AF19+AH19+AH19+AJ19+AL19 -> 41000 | H19: 41000 | W19: 41000
A20: =A19+1 -> 7 | B20: 45695 | C20: سداد عميل | D20: 7 | E20: =G20+I20+K20+M20+O20+Q20+S20+U20+W20+Y20+AA20+AC20+AE20+AG20+AG20+AI20+AK20 -> 79700 | F20: =H20+J20+L20+N20+P20+R20+T20+V20+X20+Z20+AB20+AD20+AF20+AH20+AH20+AJ20+AL20 -> 79700 | G20: 79700 | Z20: 79700
A21: =A20+1 -> 8 | E21: =G21+I21+K21+M21+O21+Q21+S21+U21+W21+Y21+AA21+AC21+AE21+AG21+AG21+AI21+AK21 -> 0 | F21: =H21+J21+L21+N21+P21+R21+T21+V21+X21+Z21+AB21+AD21+AF21+AH21+AH21+AJ21+AL21 -> 0
A22: =A21+1 -> 9 | E22: =G22+I22+K22+M22+O22+Q22+S22+U22+W22+Y22+AA22+AC22+AE22+AG22+AG22+AI22+AK22 -> 0 | F22: =H22+J22+L22+N22+P22+R22+T22+V22+X22+Z22+AB22+AD22+AF22+AH22+AH22+AJ22+AL22 -> 0
A23: =A22+1 -> 10 | E23: =G23+I23+K23+M23+O23+Q23+S23+U23+W23+Y23+AA23+AC23+AE23+AG23+AG23+AI23+AK23 -> 0 | F23: =H23+J23+L23+N23+P23+R23+T23+V23+X23+Z23+AB23+AD23+AF23+AH23+AH23+AJ23+AL23 -> 0
A24: اجمالي شهر فبراير | E24: =SUM(E14:E23) -> 627825 | F24: =SUM(F14:F23) -> 627825 | G24: =SUM(G14:G23) -> 423235 | H24: =SUM(H14:H23) -> 41000 | I24: =SUM(I14:I23) -> 0 | J24: =SUM(J14:J23) -> 0 | K24: =SUM(K14:K23) -> 163590 | L24: =SUM(L14:L23) -> 0 | ... AL24: =SUM(AL14:AL23) -> 0
A25: 1 | B25: 45717 | C25: استعاضة عهدة | D25: 8 | E25: =G25+I25+K25+M25+O25+Q25+S25+U25+W25+Y25+AA25+AC25+AE25+AG25+AG25+AI25+AK25 -> 30000 | F25: =H25+J25+L25+N25+P25+R25+T25+V25+X25+Z25+AB25+AD25+AF25+AH25+AH25+AJ25+AL25 -> 30000 | J25: 30000 | AC25: 30000
A26: =A25+1 -> 2 | B26: 45718 | C26: تسوية عهدة | D26: 9 | E26: =G26+I26+K26+M26+O26+Q26+S26+U26+W26+Y26+AA26+AC26+AE26+AG26+AG26+AI26+AK26 -> 1100 | F26: =H26+J26+L26+N26+P26+R26+T26+V26+X26+Z26+AB26+AD26+AF26+AH26+AH26+AJ26+AL26 -> 1100 | AD26: 1100 | AE26: 1100
A27: =A26+1 -> 3 | B27: 45719 | C27: تسوية عهدة | D27: 10 | E27: =G27+I27+K27+M27+O27+Q27+S27+U27+W27+Y27+AA27+AC27+AE27+AG27+AG27+AI27+AK27 -> 1500 | F27: =H27+J27+L27+N27+P27+R27+T27+V27+X27+Z27+AB27+AD27+AF27+AH27+AH27+AJ27+AL27 -> 1500 | AD27: 1500 | AE27: 1500
A28: =A27+1 -> 4 | B28: 45720 | C28: استعاضة عهدة | D28: 11 | E28: =G28+I28+K28+M28+O28+Q28+S28+U28+W28+Y28+AA28+AC28+AE28+AG28+AG28+AI28+AK28 -> 30000 | F28: =H28+J28+L28+N28+P28+R28+T28+V28+X28+Z28+AB28+AD28+AF28+AH28+AH28+AJ28+AL28 -> 30000 | J28: 30000 | AC28: 30000
A29: =A28+1 -> 5 | B29: 45721 | C29: اهلاك عهدة | D29: 12 | E29: =G29+I29+K29+M29+O29+Q29+S29+U29+W29+Y29+AA29+AC29+AE29+AG29+AG29+AI29+AK29 -> 30000 | F29: =H29+J29+L29+N29+P29+R29+T29+V29+X29+Z29+AB29+AD29+AF29+AH29+AH29+AJ29+AL29 -> 30000 | AI29: 30000 | AL29: 30000
A30: =A29+1 -> 6 | E30: =G30+I30+K30+M30+O30+Q30+S30+U30+W30+Y30+AA30+AC30+AE30+AG30+AG30+AI30+AK30 -> 0 | F30: =H30+J30+L30+N30+P30+R30+T30+V30+X30+Z30+AB30+AD30+AF30+AH30+AH30+AJ30+AL30 -> 0
A31: =A30+1 -> 7 | E31: =G31+I31+K31+M31+O31+Q31+S31+U31+W31+Y31+AA31+AC31+AE31+AG31+AG31+AI31+AK31 -> 0 | F31: =H31+J31+L31+N31+P31+R31+T31+V31+X31+Z31+AB31+AD31+AF31+AH31+AH31+AJ31+AL31 -> 0
A32: =A31+1 -> 8 | E32: =G32+I32+K32+M32+O32+Q32+S32+U32+W32+Y32+AA32+AC32+AE32+AG32+AG32+AI32+AK32 -> 0 | F32: =H32+J32+L32+N32+P32+R32+T32+V32+X32+Z32+AB32+AD32+AF32+AH32+AH32+AJ32+AL32 -> 0
A33: =A32+1 -> 9 | E33: =G33+I33+K33+M33+O33+Q33+S33+U33+W33+Y33+AA33+AC33+AE33+AG33+AG33+AI33+AK33 -> 0 | F33: =H33+J33+L33+N33+P33+R33+T33+V33+X33+Z33+AB33+AD33+AF33+AH33+AH33+AJ33+AL33 -> 0
A34: =A33+1 -> 10 | E34: =G34+I34+K34+M34+O34+Q34+S34+U34+W34+Y34+AA34+AC34+AE34+AG34+AG34+AI34+AK34 -> 0 | F34: =H34+J34+L34+N34+P34+R34+T34+V34+X34+Z34+AB34+AD34+AF34+AH34+AH34+AJ34+AL34 -> 0
A35: اجمالي شهر مارس | E35: =SUM(E25:E34) -> 92600 | F35: =SUM(F25:F34) -> 92600 | G35: =SUM(G25:G34) -> 0 | H35: =SUM(H25:H34) -> 0 | I35: =SUM(I25:I34) -> 0 | J35: =SUM(J25:J34) -> 60000 | K35: =SUM(K25:K34) -> 0 | L35: =SUM(L25:L34) -> 0 | ... AL35: =SUM(AL25:AL34) -> 30000
A36: 1
A37: =A36+1 -> 2
A38: =A37+1 -> 3
A39: =A38+1 -> 4
A40: =A39+1 -> 5
...

Sheet ميزان المراجعه
A1: ميزان مراجعة الشركة
A3: البيان | B3: الارصدةالافتتاحية | D3: الحركة | F3: الرصيد
B4: مدين | C4: دائن | D4: مدين | E4: دائن | F4: مدين | G4: دائن
A5: الأصول الثابتة | B5: =السؤال!B3 -> 200000 | F5: =B5+D5-E5 -> 200000
A6: الصندوق | B6: =السؤال!B4 -> 5000 | D6: =قيود!G137 -> 423235 | E6: =قيود!H137 -> 41000 | F6: =B6+D6-E6 -> 387235
A7: البنك | B7: =السؤال!B5 -> 1000000 | D7: =قيود!I137 -> 0 | E7: =قيود!J137 -> 60000 | F7: =B7+D7-E7 -> 940000
A8: اوراق القبض | B8: =السؤال!B6 -> 10000 | D8: 0 | E8: 0 | F8: =B8+D8-E8 -> 10000
A9: العملاء | B9: =السؤال!B7 -> 100000 | D9: =قيود!Y137 -> 0 | E9: =قيود!Z137 -> 79700 | F9: =B9+D9-E9 -> 20300
A10: تامينات لدى الغير | B10: =السؤال!B8 -> 40000 | F10: =B10+D10-E10 -> 40000
A11: راس المال | C11: =السؤال!B9 -> 1246000 | G11: 1246000
A12: موردين | C12: =السؤال!B10 -> 54000 | D12: =قيود!W137 -> 41000 | E12: =قيود!X137 -> 163590 | G12: =C12+E12-D12 -> 176590
A13: اوراق دفع | C13: =السؤال!B11 -> 10000 | G13: 10000
A14: تامينات للغير | C14: =السؤال!B12 -> 45000 | G14: 45000
A15: المخزون | D15: =قيود!K137 -> 163590 | E15: =قيود!L137 -> 0 | F15: 163590
A16: تكلفة المبيعات
A17: المبيعات | E17: =قيود!T137 -> 343535 | G17: 343535
A18: ضريبة القيمة المضافة
A19: خصم مكتسب به
A20: ضريبة أرباح تجارية مدينة
A21: ضريبة ارباح تجارية دائنة
A22: العهد | D22: =قيود!AC137 -> 60000 | E22: =قيود!AD137 -> 2600 | F22: =D22-E22 -> 57400
A23: الميزانية العمومية | D23: 2600 | F23: 2600
A24: مصروف اهلاك | D24: 30000 | F24: 30000
A25: مجمع اهلاك | E25: 30000 | G25: 30000
A26: خصم مسموح به
A27: الاجمالي | B27: =SUM(B5:B26) -> 1355000 | C27: =SUM(C5:C26) -> 1355000 | D27: =SUM(D5:D26) -> 720425 | E27: =SUM(E5:E26) -> 720425 | F27: =SUM(F5:F26) -> 1851125 | G27: =SUM(G5:G26) -> 1851125

Sheet الايضاحات المتممة
A1: الايضاحات المتممة للشركة
A2: الممتلكات والالات والمعدات
A3: البيان | B3: رس
A4: مباني | B4: 5000
A5: سيارات | B5: 5000
A6: الالات | B6: 5000
A7: اثاث | B7: 5000
A8: اجمالي | B8: =SUM(B4:B7) -> 20000
A9: مشروعات تحت التنفيذ
A10: البيان | B10: رس
A11: تكوين سلعي | B11: 0
A12: انفاق استثمارية | B12: 0
A13: الاجمالي | B13: 0
A14: نقدية بالبنك والصندوق
A15: البيام | B15: رس
A16: النقد بالصندوق | B16: ='ميزان المراجعه'!F6 -> 387235
A17: النقد بالبنك | B17: ='ميزان المراجعه'!F7 -> 940000
A18: الاحمالي | B18: =SUM(B16+B17) -> 1327235
A19: صافي الايرادات
A20: البيان | B20: رس
A21: الايرادات | B21: 343535
A22: يخصم | B22: 0
A23: مردودات مبيعات | B23: 0
A24: الخصم المسموح به | B24: 0
A25: الاجمالي | B25: =SUM(B21) -> 343535
A26: اصول اخرى غير ملموسة
A27: البيان
A28: شهرة | B28: 0
A29: حق امتياز | B29: 0
A30: الاجمالي | B30: 0
A31: بنوك دائنة
A32: البيان
A33: سحب على االمكشوف | B33: 0
A34: تسهيلات ائتمانية | B34: 0
A35: الاجمالي | B35: 0
A36: تكلفة المبيعات جرد مستمر
A37: البيان | B37: 0
A38: تكلفة المبيعات جرد مستمر | B38: 0
A39: يخصم | B39: 0
A40: خصم مكتسب | B40: 0
...

Sheet قائمة الدخل
A1: البند | B1: مدين | C1: دائن
A2: المبيعات | C2: =قيود!T137 -> 343535
A3: مصروف الإهلاك | B3: 30000
A4: صافي الربح قبل الضريبة | C4: =C2-B3 -> 313535
A5: ضريبة أرباح تجارية (افتراض لا يوجد)
A6: صافي الربح للفترة | C6: =C4 -> 313535

Sheet قائمة المركز المالي
A1: البند | B1: المبلغ (ريال) | D1: البند | E1: المبلغ (ريال)
A2: الأصول الثابتة | B2: ='ميزان المراجعه'!B5 -> 200000
A3: الصندوق | B3: ='ميزان المراجعه'!F6 -> 387235 | D3: موردون | E3: ='ميزان المراجعه'!G12 -> 176590
A4: البنك | B4: ='ميزان المراجعه'!F7 -> 940000 | D4: أوراق الدفع | E4: ='ميزان المراجعه'!G13 -> 10000
A5: اوراق القبض | B5: ='ميزان المراجعه'!F8 -> 10000 | D5: تأمينات للغير | E5: ='ميزان المراجعه'!G14 -> 45000
A6: العملاء | B6: ='ميزان المراجعه'!F9 -> 20300 | D6: إجمالي الخصوم المتداولة | E6: =E4+E5+E2+E3 -> 231590
A7: تامينات لدى الغير | B7: ='ميزان المراجعه'!F10 -> 40000 | D7: رأس المال | E7: ='ميزان المراجعه'!G11 -> 1246000
A8: المخزون | B8: ='ميزان المراجعه'!F15 -> 163590 | D8: صافي الربح للفترة | E8: ='قائمة الدخل'!C6 -> 313535
A9: العهد | B9: ='ميزان المراجعه'!F22 -> 57400 | D9: إجمالي حقوق الملكية | E9: =E7+E8 -> 1559535
A10: الميزانية العمومية | B10: ='ميزان المراجعه'!F23 -> 2600 | D10: إجمالي الخصوم وحقوق الملكية | E10: =E6+E9 -> 1791125
A11: مجمع اهلاك | B11: ='ميزان المراجعه'!G25 -> 30000
A12: إجمالي الأصول | B12: =SUM(B2:B10)-B11 -> 1791125
