Workbook

Sheet CS
B2: Case Study: Tara's Maids Cleaning Service, Ltd.
B3: Tara Harris opened Tara's Maids Cleaning Service, Ltd. on July 1, 2017. During July, the company completed the following transactions:
B4: · July 1: Shareholders invested £15,000 cash in the business in exchange for ordinary shares.
B5: · July 1: Purchased a used truck for £10,000, paying £3,000 cash and the balance on account.
B6: · July 3: Purchased cleaning supplies for £1,700 on account.
B7: · July 5: Paid £1,800 on a one-year insurance policy, effective July 1.
B8: · July 12: Billed customers £4,200 for cleaning services performed.
B9: · July 18: Paid £1,000 of amount owed on truck, and £400 of amount owed on cleaning supplies.
B10: · July 20: Paid £1,900 for employee salaries.
B11: · July 21: Collected £2,400 from customers billed on July 12.
B12: · July 25: Billed customers £2,100 for cleaning services performed.
B13: · July 31: Paid gasoline for the month on the truck, £400.
... B27: 7. Prepare a post-closing trial balance at July 31.

Sheet J1
A1: TARA'S MAIDS CLEANING SERVICE, LTD.
A2: General Journal – Page J1
A3: For the Month Ended July 31, 2017
A4: Date | B4: Account Titles and Explanation | C4: Ref. | D4: Debit (£) | E4: Credit (£)
A5: Jul 1 | B5: Cash | C5: 101 | D5: 15000
B6: Share Capital—Ordinary | C6: 311 | E6: 15000
B7: (Shareholders invested cash for ordinary shares)
A8: Jul 1 | B8: Equipment | C8: 157 | D8: 10000
B9: Cash | C9: 101 | E9: 3000
B10: Accounts Payable | C10: 201 | E10: 7000
B11: (Purchased truck; £3,000 cash + £7,000 on account)
A12: Jul 3 | B12: Supplies | C12: 126 | D12: 1700
B13: Accounts Payable | C13: 201 | E13: 1700
B14: (Purchased cleaning supplies on account)
A15: Jul 5 | B15: Prepaid Insurance | C15: 130 | D15: 1800
B16: Cash | C16: 101 | E16: 1800
B17: (Paid 1-year insurance policy, effective July 1)
A18: Jul 12 | B18: Accounts Receivable | C18: 112 | D18: 4200
B19: Service Revenue | C19: 400 | E19: 4200
B20: (Billed customers for cleaning services)
A21: Jul 18 | B21: Accounts Payable | C21: 201 | D21: 1400
B22: Cash | C22: 101 | E22: 1400
B23: (Paid £1,000 on truck + £400 on supplies)
A24: Jul 20 | B24: Salaries and Wages Expense | C24: 726 | D24: 1900
B25: Cash | C25: 101 | E25: 1900
B26: (Paid employee salaries)
A27: Jul 21 | B27: Cash | C27: 101 | D27: 2400
B28: Accounts Receivable | C28: 112 | E28: 2400
B29: (Collected from customers billed July 12)
A30: Jul 25 | B30: Accounts Receivable | C30: 112 | D30: 2100
B31: Service Revenue | C31: 400 | E31: 2100
B32: (Billed customers for cleaning services)
A33: Jul 31 | B33: Gasoline Expense | C33: 633 | D33: 400
B34: Cash | C34: 101 | E34: 400
B35: (Paid gasoline expense for the month)
A36: Jul 31 | B36: Dividends | C36: 332 | D36: 500
B37: Cash | C37: 101 | E37: 500
B38: (Declared and paid cash dividend)

Sheet J2
A1: TARA'S MAIDS CLEANING SERVICE, LTD.
A2: General Journal – Page J2 (Adjusting Entries)
A3: July 31, 2017
A4: Date | B4: Account Titles and Explanation | C4: Ref. | D4: Debit (£) | E4: Credit (£)
A5: Jul 31 | B5: Accounts Receivable | C5: 112 | D5: 1300
B6: Service Revenue | C6: 400 | E6: 1300
B7: (Unbilled fees for services performed at July 31)
A8: Jul 31 | B8: Depreciation Expense | C8: 711 | D8: 200
B9: Accum. Depr.—Equipment | C9: 158 | E9: 200
B10: (Depreciation on equipment for July)
A11: Jul 31 | B11: Insurance Expense | C11: 722 | D11: 150
B12: Prepaid Insurance | C12: 130 | E12: 150
B13: (1/12 of £1,800 annual insurance expired)
A14: Jul 31 | B14: Supplies Expense | C14: 631 | D14: 1420
B15: Supplies | C15: 126 | E15: 1420
B16: (Supplies used: £1,700 − £280 on hand)
A17: Jul 31 | B17: Salaries and Wages Expense | C17: 726 | D17: 630
B18: Salaries and Wages Payable | C18: 212 | E18: 630
B19: (Accrued but unpaid salaries at July 31)

Sheet J3
A1: TARA'S MAIDS CLEANING SERVICE, LTD.
A2: General Journal – Page J3 (Closing Entries)
A3: July 31, 2017
A4: Date | B4: Account Titles and Explanation | C4: Ref. | D4: Debit (£) | E4: Credit (£)
A5: Jul 31 | B5: Service Revenue | C5: 400 | D5: ='J1'!E19+'J1'!E31+'J2'!E6 -> 7600
B6: Income Summary | C6: 350 | E6: =D5 -> 7600
B7: (Close revenue accounts to Income Summary)
A8: Jul 31 | B8: Income Summary | C8: 350 | D8: ='J1'!D24+'J2'!D17+'J2'!D14+'J1'!D33+'J2'!D8+'J2'!D11 -> 4700
B9: Salaries and Wages Expense | C9: 726 | E9: ='J1'!D24+'J2'!D17 -> 2530
B10: Supplies Expense | C10: 631 | E10: ='J2'!D14 -> 1420
B11: Gasoline Expense | C11: 633 | E11: ='J1'!D33 -> 400
B12: Depreciation Expense | C12: 711 | E12: ='J2'!D8 -> 200
B13: Insurance Expense | C13: 722 | E13: ='J2'!D11 -> 150
B14: (Close expense accounts to Income Summary)
A15: Jul 31 | B15: Income Summary | C15: 350 | D15: =D5-D8 -> 2900
B16: Retained Earnings | C16: 320 | E16: =D15 -> 2900
B17: (Close Income Summary to Retained Earnings)
A18: Jul 31 | B18: Retained Earnings | C18: 320 | D18: ='J1'!D36 -> 500
B19: Dividends | C19: 332 | E19: ='J1'!D36 -> 500
B20: (Close Dividends to Retained Earnings)

Sheet Ledger
A1: TARA'S MAIDS CLEANING SERVICE, LTD.
A2: General Ledger – T-Accounts
A3: For the Month Ended July 31, 2017
A5: Cash – No. 101
A6: Date | B6: Explanation | C6: Ref. | D6: Debit (£) | E6: Credit (£) | F6: Balance (£)
A7: Jul 1 | B7: J1 | C7: J1 | D7: ='J1'!D5 -> 15000 | F7: =D7-(0) -> 15000
A8: Jul 1 | B8: J1 | C8: J1 | E8: ='J1'!E9 -> 3000 | F8: =D7-(E8) -> 12000
A9: Jul 5 | B9: J1 | C9: J1 | E9: ='J1'!E16 -> 1800 | F9: =D7-(E8+E9) -> 10200
A10: Jul 18 | B10: J1 | C10: J1 | E10: ='J1'!E22 -> 1400 | F10: =D7-(E8+E9+E10) -> 8800
A11: Jul 20 | B11: J1 | C11: J1 | E11: ='J1'!E25 -> 1900 | F11: =D7-(E8+E9+E10+E11) -> 6900
A12: Jul 21 | B12: J1 | C12: J1 | D12: ='J1'!D27 -> 2400 | F12: =D7+D12-(E8+E9+E10+E11) -> 9300
A13: Jul 31 | B13: J1 | C13: J1 | E13: ='J1'!E34 -> 400 | F13: =D7+D12-(E8+E9+E10+E11+E13) -> 8900
A14: Jul 31 | B14: J1 | C14: J1 | E14: ='J1'!E37 -> 500 | F14: =D7+D12-(E8+E9+E10+E11+E13+E14) -> 8400
A15: Jul 31 | B15: Closing Balance | F15: =D7+D12-(E8+E9+E10+E11+E13+E14) -> 8400
A17: Accounts Receivable – No. 112
A18: Date | B18: Explanation | C18: Ref. | D18: Debit (£) | E18: Credit (£) | F18: Balance (£)
A19: Jul 12 | B19: J1 | C19: J1 | D19: ='J1'!D18 -> 4200 | F19: =D19-(0) -> 4200
A20: Jul 21 | B20: J1 | C20: J1 | E20: ='J1'!E28 -> 2400 | F20: =D19-(E20) -> 1800
A21: Jul 25 | B21: J1 | C21: J1 | D21: ='J1'!D30 -> 2100 | F21: =D19+D21-(E20) -> 3900
A22: Jul 31 | B22: Adj J2 | C22: J2 | D22: ='J2'!D5 -> 1300 | F22: =D19+D21+D22-(E20) -> 5200
A23: Jul 31 | B23: Closing Balance | F23: =D19+D21+D22-(E20) -> 5200
A25: Supplies – No. 126
A26: Date | B26: Explanation | C26: Ref. | D26: Debit (£) | E26: Credit (£) | F26: Balance (£)
A27: Jul 3 | B27: J1 | C27: J1 | D27: ='J1'!D12 -> 1700 | F27: =D27-(0) -> 1700
A28: Jul 31 | B28: Adj J2 | C28: J2 | E28: ='J2'!E15 -> 1420 | F28: =D27-(E28) -> 280
A29: Jul 31 | B29: Closing Balance | F29: =D27-(E28) -> 280
A31: Prepaid Insurance – No. 130
A32: Date | B32: Explanation | C32: Ref. | D32: Debit (£) | E32: Credit (£) | F32: Balance (£)
A33: Jul 5 | B33: J1 | C33: J1 | D33: ='J1'!D15 -> 1800 | F33: =D33-(0) -> 1800
A34: Jul 31 | B34: Adj J2 | C34: J2 | E34: ='J2'!E12 -> 150 | F34: =D33-(E34) -> 1650
A35: Jul 31 | B35: Closing Balance | F35: =D33-(E34) -> 1650
A37: Equipment – No. 157
A38: Date | B38: Explanation | C38: Ref. | D38: Debit (£) | E38: Credit (£) | F38: Balance (£)
A39: Jul 1 | B39: J1 | C39: J1 | D39: ='J1'!D8 -> 10000 | F39: =D39-(0) -> 10000
A40: Jul 31 | B40: Closing Balance | F40: =D39-(0) -> 10000
A42: Accum. Depr.—Equipment – No. 158
A43: Date | B43: Explanation | C43: Ref. | D43: Debit (£) | E43: Credit (£) | F43: Balance (£)
A44: Jul 31 | B44: Adj J2 | C44: J2 | E44: ='J2'!E9 -> 200 | F44: =0-(E44) -> -200
A45: Jul 31 | B45: Closing Balance | F45: =0-(E44) -> -200
A47: Accounts Payable – No. 201
...

Sheet Worksheet
A1: TARA'S MAIDS CLEANING SERVICE, LTD.
A2: Worksheet
A3: For the Month Ended July 31, 2017
A4: Account Titles | B4: Trial Balance | D4: Adjustments | F4: Adjusted Trial Bal. | H4: Income Statement
B5: Dr. | C5: Cr. | D5: Dr. | E5: Cr. | F5: Dr. | G5: Cr. | H5: Dr. | I5: Cr.
A6: Cash | B6: ='J1'!D5+'J1'!D27-( 'J1'!E9+'J1'!E16+'J1'!E22+'J1'!E25+'J1'!E34+'J1'!E37) -> 8400 | F6: =IFERROR(B6,0)+IFERROR(D6,0)-IFERROR(E6,0) -> 8400
A7: Accounts Receivable | B7: ='J1'!D18+'J1'!D30-( 'J1'!E28) -> 3900 | D7: ='J2'!D5 -> 1300 | F7: =IFERROR(B7,0)+IFERROR(D7,0)-IFERROR(E7,0) -> 5200
A8: Supplies | B8: ='J1'!D12 -> 1700 | E8: ='J2'!E15 -> 1420 | F8: =IFERROR(B8,0)+IFERROR(D8,0)-IFERROR(E8,0) -> 280
A9: Prepaid Insurance | B9: ='J1'!D15 -> 1800 | E9: ='J2'!E12 -> 150 | F9: =IFERROR(B9,0)+IFERROR(D9,0)-IFERROR(E9,0) -> 1650
A10: Equipment | B10: ='J1'!D8 -> 10000 | F10: =IFERROR(B10,0)+IFERROR(D10,0)-IFERROR(E10,0) -> 10000
A11: Accounts Payable | C11: ='J1'!E10+'J1'!E13-( 'J1'!D21) -> 7300 | G11: =IFERROR(C11,0)+IFERROR(E11,0)-IFERROR(D11,0) -> 7300
A12: Share Capital—Ordinary | C12: ='J1'!E6 -> 15000 | G12: =IFERROR(C12,0)+IFERROR(E12,0)-IFERROR(D12,0) -> 15000
A13: Dividends | B13: ='J1'!D36 -> 500 | F13: =IFERROR(B13,0)+IFERROR(D13,0)-IFERROR(E13,0) -> 500
A14: Service Revenue | C14: ='J1'!E19+'J1'!E31 -> 6300 | E14: ='J2'!E6 -> 1300 | G14: =IFERROR(C14,0)+IFERROR(E14,0)-IFERROR(D14,0) -> 7600 | I14: =G14 -> 7600
A15: Gasoline Expense | B15: ='J1'!D33 -> 400 | F15: =IFERROR(B15,0)+IFERROR(D15,0)-IFERROR(E15,0) -> 400 | H15: =F15 -> 400
A16: Salaries & Wages Expense | B16: ='J1'!D24 -> 1900 | D16: ='J2'!D17 -> 630 | F16: =IFERROR(B16,0)+IFERROR(D16,0)-IFERROR(E16,0) -> 2530 | H16: =F16 -> 2530
A17: Depreciation Expense | D17: ='J2'!D8 -> 200 | F17: =IFERROR(B17,0)+IFERROR(D17,0)-IFERROR(E17,0) -> 200 | H17: =F17 -> 200
A18: Accum. Depr.—Equipment | E18: ='J2'!E9 -> 200 | G18: =IFERROR(C18,0)+IFERROR(E18,0)-IFERROR(D18,0) -> 200
A19: Insurance Expense | D19: ='J2'!D11 -> 150 | F19: =IFERROR(B19,0)+IFERROR(D19,0)-IFERROR(E19,0) -> 150 | H19: =F19 -> 150
A20: Supplies Expense | D20: ='J2'!D14 -> 1420 | F20: =IFERROR(B20,0)+IFERROR(D20,0)-IFERROR(E20,0) -> 1420 | H20: =F20 -> 1420
A21: Salaries & Wages Payable | E21: ='J2'!E18 -> 630 | G21: =IFERROR(C21,0)+IFERROR(E21,0)-IFERROR(D21,0) -> 630
A22: Totals | B22: =SUM(B6:B21) -> 28600 | C22: =SUM(C6:C21) -> 28600 | D22: =SUM(D6:D21) -> 3700 | E22: =SUM(E6:E21) -> 3700 | F22: =SUM(F6:F21) -> 30730 | G22: =SUM(G6:G21) -> 30730 | H22: =SUM(H6:H21) -> 4700 | I22: =SUM(I6:I21) -> 7600
A23: Net Income | H23: =I22-H22 -> 2900
A24: Final Totals | H24: =H22+H23 -> 7600 | I24: =I22 -> 7600

Sheet Financial Statements
A1: TARA'S MAIDS CLEANING SERVICE, LTD.
A2: Income Statement
A3: For the Month Ended July 31, 2017
A5: Revenues
A6: Service Revenue | C6: =Worksheet!G14 -> 7600
A8: Expenses
A9: Salaries & Wages Expense | B9: =Worksheet!F16 -> 2530
A10: Supplies Expense | B10: =Worksheet!F20 -> 1420
A11: Gasoline Expense | B11: =Worksheet!F15 -> 400
A12: Depreciation Expense | B12: =Worksheet!F17 -> 200
A13: Insurance Expense | B13: =Worksheet!F19 -> 150
A14: Total Expenses | C14: =B9+B10+B11+B12+B13 -> 4700
A15: Net Income | C15: =C6-C14 -> 2900
A18: TARA'S MAIDS CLEANING SERVICE, LTD.
A19: Retained Earnings Statement
A20: For the Month Ended July 31, 2017
A22: Retained Earnings, July 1 | C22: 0
A23: Add: Net Income | B23: ='Financial Statements'!C15 -> 2900
A24: Less: Dividends | B24: =Worksheet!F13 -> 500
A25: Retained Earnings, July 31 | C25: =0+B23-B24 -> 2400
A28: TARA'S MAIDS CLEANING SERVICE, LTD.
A29: Statement of Financial Position
A30: July 31, 2017
A32: ASSETS
A33: Property, Plant, and Equipment
A34: Equipment | B34: =Worksheet!F10 -> 10000
A35: Less: Accumulated Depreciation—Equipment | B35: =Worksheet!G18 -> 200
A36: Net Equipment | C36: =B34-B35 -> 9800
A37: Current Assets
A38: Prepaid Insurance | B38: =Worksheet!F9 -> 1650
A39: Supplies | B39: =Worksheet!F8 -> 280
A40: Accounts Receivable | B40: =Worksheet!F7 -> 5200
A41: Cash | B41: =Worksheet!F6 -> 8400
A42: Total Current Assets | C42: =B38+B39+B40+B41 -> 15530
A43: TOTAL ASSETS | C43: =C36+C42 -> 25330
A46: EQUITY AND LIABILITIES
A47: Equity
A48: Share Capital—Ordinary | B48: =Worksheet!G12 -> 15000
A49: Retained Earnings | B49: ='Financial Statements'!C25 -> 2400
A50: Total Equity | C50: =B48+B49 -> 17400
...

Sheet Post-Closing TB
A1: TARA'S MAIDS CLEANING SERVICE, LTD.
A2: Post-Closing Trial Balance
A3: July 31, 2017
A4: Account Title | B4: Debit (£) | C4: Credit (£)
A5: Cash | B5: =Ledger!F15 -> 8400
A6: Accounts Receivable | B6: =Ledger!F23 -> 5200
A7: Supplies | B7: =Ledger!F29 -> 280
A8: Prepaid Insurance | B8: =Ledger!F35 -> 1650
A9: Equipment | B9: =Ledger!F40 -> 10000
A10: Accum. Depr.—Equipment | C10: 200
A11: Accounts Payable | C11: 7300
A12: Salaries & Wages Payable | C12: 630
A13: Share Capital—Ordinary | C13: 15000
A14: Retained Earnings | C14: 2400
A15: Totals | B15: =SUM(B5:B14) -> 25530 | C15: 25530
A17: =IF(B15=C15,"✓ Balanced! Debits = Credits = "&TEXT(B15,"£#,##0"),"✗ NOT Balanced!") -> ✓ Balanced! Debits = Credits = £25,530
